<?xml version="1.0" ?>
<robot name="demo" xmlns:xacro="http://www.ros.org/wiki/xacro">

<xacro:include filename="$(find demo_description)/urdf/materials.xacro" />
<xacro:include filename="$(find demo_description)/urdf/demo.trans" />
<xacro:include filename="$(find demo_description)/urdf/demo.gazebo" />
<link name="base_link">
  <inertial>
    <origin xyz="5.444805393558335e-15 -0.00027351689818956874 0.01987626616510473" rpy="0 0 0"/>
    <mass value="1.2783826690745435"/>
    <inertia ixx="0.004451" iyy="0.002564" izz="0.006667" ixy="0.0" iyz="-1.2e-05" ixz="0.0"/>
  </inertial>
  <visual>
    <origin xyz="0 0 0" rpy="0 0 0"/>
    <geometry>
      <mesh filename="file://$(find demo_description)/meshes/base_link.stl" scale="0.001 0.001 0.001"/>
    </geometry>
    <material name="silver"/>
  </visual>
  <collision>
    <origin xyz="0 0 0" rpy="0 0 0"/>
    <geometry>
      <mesh filename="file://$(find demo_description)/meshes/base_link.stl" scale="0.001 0.001 0.001"/>
    </geometry>
  </collision>
</link>

<link name="right_wheel_1">
  <inertial>
    <origin xyz="-0.009999999999999995 0.0 0.0" rpy="0 0 0"/>
    <mass value="0.09349379737083224"/>
    <inertia ixx="7.5e-05" iyy="4.1e-05" izz="4.1e-05" ixy="-0.0" iyz="0.0" ixz="0.0"/>
  </inertial>
  <visual>
    <origin xyz="0.08 -0.08 -0.02" rpy="0 0 0"/>
    <geometry>
      <mesh filename="file://$(find demo_description)/meshes/right_wheel_1.stl" scale="0.001 0.001 0.001"/>
    </geometry>
    <material name="silver"/>
  </visual>
  <collision>
    <origin xyz="0.08 -0.08 -0.02" rpy="0 0 0"/>
    <geometry>
      <mesh filename="file://$(find demo_description)/meshes/right_wheel_1.stl" scale="0.001 0.001 0.001"/>
    </geometry>
  </collision>
</link>

<link name="left_wheel_1">
  <inertial>
    <origin xyz="0.009999999999999995 0.0 0.0" rpy="0 0 0"/>
    <mass value="0.09349379737083224"/>
    <inertia ixx="7.5e-05" iyy="4.1e-05" izz="4.1e-05" ixy="0.0" iyz="0.0" ixz="0.0"/>
  </inertial>
  <visual>
    <origin xyz="-0.08 -0.08 -0.02" rpy="0 0 0"/>
    <geometry>
      <mesh filename="file://$(find demo_description)/meshes/left_wheel_1.stl" scale="0.001 0.001 0.001"/>
    </geometry>
    <material name="silver"/>
  </visual>
  <collision>
    <origin xyz="-0.08 -0.08 -0.02" rpy="0 0 0"/>
    <geometry>
      <mesh filename="file://$(find demo_description)/meshes/left_wheel_1.stl" scale="0.001 0.001 0.001"/>
    </geometry>
  </collision>
</link>

<link name="camera_1">
  <inertial>
    <origin xyz="0.0 0.020000000000000004 0.010000000000000002" rpy="0 0 0"/>
    <mass value="0.03392"/>
    <inertia ixx="2e-06" iyy="1.9e-05" izz="1.9e-05" ixy="0.0" iyz="0.0" ixz="0.0"/>
  </inertial>
  <visual>
    <origin xyz="-0.0 0.1 -0.04" rpy="0 0 0"/>
    <geometry>
      <mesh filename="file://$(find demo_description)/meshes/camera_1.stl" scale="0.001 0.001 0.001"/>
    </geometry>
    <material name="silver"/>
  </visual>
  <collision>
    <origin xyz="-0.0 0.1 -0.04" rpy="0 0 0"/>
    <geometry>
      <mesh filename="file://$(find demo_description)/meshes/camera_1.stl" scale="0.001 0.001 0.001"/>
    </geometry>
  </collision>
</link>

<joint name="Revolute 1" type="continuous">
  <origin xyz="-0.08 0.08 0.02" rpy="0 0 0"/>
  <parent link="base_link"/>
  <child link="right_wheel_1"/>
  <axis xyz="1.0 0.0 0.0"/>
</joint>

<joint name="Revolute 2" type="continuous">
  <origin xyz="0.08 0.08 0.02" rpy="0 0 0"/>
  <parent link="base_link"/>
  <child link="left_wheel_1"/>
  <axis xyz="1.0 0.0 0.0"/>
</joint>

<joint name="Rigid 3" type="fixed">
  <origin xyz="0.0 -0.1 0.04" rpy="0 0 0"/>
  <parent link="base_link"/>
  <child link="camera_1"/>
</joint>

</robot>
